<?xml version="1.0" ?>
<robot name="pendulum2l">
  <link name="link0">
		<visual>
			<origin xyz = "0 0 0" />
			<geometry>
				<box size = "0.5 0.5 0.1" />
			</geometry>
			<material name = "gray A">
				<color rgba = "0.1 0.1 0.1 1" />
			</material>
		</visual>
		<inertial>
			<origin xyz = "0 0 -0.5" />
			<mass value = "0.5" />
			<inertia ixx = "0.5" iyy = "0.5" izz = "0.5" ixy = "0" ixz = "0" iyz = "0" />
		</inertial>
  </link>
  <link name="link1">
		<visual>
			<origin xyz = "0 0 -0.5" />
			<geometry>
				<cylinder radius = "0.05" length = "1"  />
			</geometry>
			<material name = "gray B">
				<color rgba = "0.3 0.3 0.3 1" />
			</material>
		</visual>
		<inertial>
			<origin xyz = "0 0 -0.0" />
			<mass value = "0.5" />
			<inertia ixx = "0.5" iyy = "0.5" izz = "0.5" ixy = "0" ixz = "0" iyz = "0" />
		</inertial>
  </link>
  <joint name="joint1" type="revolute">
    <origin xyz = "0 0 -0.05" />
    <parent link="link0"/>
    <child link="link1"/>
    <axis xyz="0 0 1"/>
    <limit effort="87" velocity="2.1750"/>
  </joint>
</robot>
