<?xml version="1.0"?>
<robot name = "pendulum1l">
	<!-- links section -->
	<link name = "base">
		<inertial>
			<origin xyz = "0 0 -0.5" />
			<mass value = "0.5" />
			<inertia ixx = "0.5" iyy = "0.5" izz = "0.5" ixy = "0" ixz = "0" iyz = "0" />
		</inertial>
		<visual>
			<origin xyz = "0 0 0" />
			<geometry>
				<box size = "0.5 0.5 0.1" />
			</geometry>
			<material name = "gray A">
				<color rgba = "0.1 0.1 0.1 1" />
			</material>
		</visual>
	</link>
	<link name = "link0">
		<inertial>
			<origin xyz = "0 0 -0.0" />
			<mass value = "0.5" />
			<inertia ixx = "0.5" iyy = "0.5" izz = "0.5" ixy = "0" ixz = "0" iyz = "0" />
		</inertial>
		<visual>
			<origin xyz = "0 0 -0.5" />
			<geometry>
				<cylinder radius = "0.05" length = "1"  />
			</geometry>
			<material name = "gray B">
				<color rgba = "0.3 0.3 0.3 1" />
			</material>
		</visual>
	</link>

	<!-- joints section -->
	<joint name = "joint0" type = "revolute">
		<parent link = "base" />
		<child link = "link0" />
		<origin rpy="0 0 0" xyz = "0 0 -0.05" />
		<axis xyz = "0 1 0" />
		<limit effort="87" lower="-2.8973" upper="2.8973" velocity="2.1750"/>
	</joint>
</robot>